<?xml version='1.0'?>
<sdf version='1.6'>
  <enable_lockstep>false</enable_lockstep>
  <model name='px4vision_sls_gazebo'>
  <static>false</static>

  <link name='base_link'>
    <pose>0 0 0 0 -0 0</pose>
    <inertial>
      <pose>0 0 0 0 -0 0</pose>
      <mass>1.5</mass>
      <inertia>
        <ixx>0.029125</ixx>
        <ixy>0</ixy>
        <ixz>0</ixz>
        <iyy>0.029125</iyy>
        <iyz>0</iyz>
        <izz>0.055225</izz>
      </inertia>
    </inertial>
    <collision name='base_link_inertia_collision'>
      <pose>0 0 0 0 -0 0</pose>
      <geometry>
        <box>
          <size>0.365 0.365 0.11</size>
        </box>
      </geometry>
      <surface>
        <contact>
          <ode>
            <min_depth>0.001</min_depth>
            <max_vel>0</max_vel>
          </ode>
        </contact>
        <friction>
          <ode/>
        </friction>
      </surface>
    </collision>
    <visual name='base_link_inertia_visual'>
      <pose>0 0 0 1.5707 0 -0.01</pose>
      <geometry>
        <mesh>
          <scale>0.001 0.001 0.001</scale>
          <uri>model://px4vision/meshes/body.dae</uri>
        </mesh>
      </geometry>
      <material>
        <script>
          <name>Gazebo/DarkGrey</name>
          <uri>file://media/materials/scripts/gazebo.material</uri>
        </script>
      </material>
    </visual>
    <gravity>1</gravity>
    <velocity_decay/>
  </link>

  <plugin name='rosbag' filename='libgazebo_multirotor_base_plugin.so'>
    <robotNamespace/>
    <linkName>base_link</linkName>
    <rotorVelocitySlowdownSim>10</rotorVelocitySlowdownSim>
  </plugin>

  <link name='pendulum'>
    <pose>0 0 -0.425 0 0 0</pose>
    <inertial>
      <mass>0.01</mass>
      <inertia>
        <ixx>0.00060208</ixx>
        <ixy>0</ixy>
        <ixz>0</ixz>
        <iyy>0.00060208</iyy>
        <iyz>0</iyz>
        <izz>0.000000005</izz>
      </inertia>
    </inertial>

    <visual name='pendulum_visual'>
      <geometry>
        <cylinder>
          <radius>0.001</radius>
          <length>0.85</length>
        </cylinder>
      </geometry>
      <material>
        <script>
          <name>Gazebo/White</name>
          <uri>file://media/materials/scripts/gazebo.material</uri>
        </script>
      </material>
    </visual>
    <gravity>1</gravity>

  </link>

  <link name='load'>
    <pose>0 0 -0.85 0 0 0</pose>
    <inertial>
      <mass>0.25</mass>
      <inertia>
        <ixx>0.0000625</ixx>
        <ixy>0</ixy>
        <ixz>0</ixz>
        <iyy>0.0000625</iyy>
        <iyz>0</iyz>
        <izz>0.0000625</izz>
      </inertia>
    </inertial>

    <visual name='load_visual'>
      <geometry>
        <sphere>
          <radius>0.025 0.025 0.025</radius>
        </sphere>
      </geometry>
      <material>
        <script>
          <name>Gazebo/Red</name>
          <uri>file://media/materials/scripts/gazebo.material</uri>
        </script>
      </material>
    </visual>
    <gravity>1</gravity>
  </link>

  <joint name='load_joint' type='ball'>
    <pose>0 0 0.0 0 0 0</pose>
    <child>load</child>
    <parent>pendulum</parent>
  </joint>

  <joint name='pendulum_joint' type='universal'>
    <pose>0 0 0.425 0 0 0</pose>
    <child>pendulum</child>
    <parent>base_link</parent>
  </joint>

  <plugin name="GazeboSlsForceControlPlugin" filename="libgazebo_sls_force_control_plugin.so" />

  </model>
</sdf>
